id:104
user_name:localhost
user_id:127.0.0.1
script:ICAN QA Service
start_time:1570425360109
command:/home/cppxaxa/Downloads/ICAN/ScriptServer/ImageDescriptors/QAService.py
exit_code:-15
>>>>>  OUTPUT STARTED <<<<<
Did not use initialization regex that was passed: .*bias_hh.*
Did not use initialization regex that was passed: .*weight_ih.*
Did not use initialization regex that was passed: .*bias_ih.*
Did not use initialization regex that was passed: .*weight_hh.*
MML model file for initializing weights is passed, but does not exist. This is fine if you're just decoding.
 * Serving Flask app "QAService" (lazy loading)
 * Environment: production
[31m   WARNING: This is a development server. Do not use it in a production deployment.[0m
[2m   Use a production WSGI server instead.[0m
 * Debug mode: off
INFO:werkzeug: * Running on http://127.0.0.1:5002/ (Press CTRL+C to quit)
INFO:werkzeug:127.0.0.1 - - [07/Oct/2019 10:46:27] "[33mGET / HTTP/1.1[0m" 404 -
INFO:werkzeug:127.0.0.1 - - [07/Oct/2019 10:46:27] "[33mGET /favicon.ico HTTP/1.1[0m" 404 -
WARNING:allennlp.data.fields.sequence_label_field:Your label namespace was 'pos'. We recommend you use a namespace ending with 'labels' or 'tags', so we don't add UNK and PAD tokens by default to your vocabulary.  See documentation for `non_padded_namespaces` parameter in Vocabulary.
===
Unable to establish connection, perhaps arango is not running.
===
ERROR:QAService:Exception on /qa [GET]
Traceback (most recent call last):
  File "/home/cppxaxa/.local/lib/python3.6/site-packages/urllib3/connection.py", line 157, in _new_conn
    (self._dns_host, self.port), self.timeout, **extra_kw
  File "/home/cppxaxa/.local/lib/python3.6/site-packages/urllib3/util/connection.py", line 84, in create_connection
    raise err
  File "/home/cppxaxa/.local/lib/python3.6/site-packages/urllib3/util/connection.py", line 74, in create_connection
    sock.connect(sa)
ConnectionRefusedError: [Errno 111] Connection refused

During handling of the above exception, another exception occurred:

Traceback (most recent call last):
  File "/home/cppxaxa/.local/lib/python3.6/site-packages/urllib3/connectionpool.py", line 672, in urlopen
    chunked=chunked,
  File "/home/cppxaxa/.local/lib/python3.6/site-packages/urllib3/connectionpool.py", line 387, in _make_request
    conn.request(method, url, **httplib_request_kw)
  File "/usr/lib/python3.6/http/client.py", line 1239, in request
    self._send_request(method, url, body, headers, encode_chunked)
  File "/usr/lib/python3.6/http/client.py", line 1285, in _send_request
    self.endheaders(body, encode_chunked=encode_chunked)
  File "/usr/lib/python3.6/http/client.py", line 1234, in endheaders
    self._send_output(message_body, encode_chunked=encode_chunked)
  File "/usr/lib/python3.6/http/client.py", line 1026, in _send_output
    self.send(msg)
  File "/usr/lib/python3.6/http/client.py", line 964, in send
    self.connect()
  File "/home/cppxaxa/.local/lib/python3.6/site-packages/urllib3/connection.py", line 184, in connect
    conn = self._new_conn()
  File "/home/cppxaxa/.local/lib/python3.6/site-packages/urllib3/connection.py", line 169, in _new_conn
    self, "Failed to establish a new connection: %s" % e
urllib3.exceptions.NewConnectionError: <urllib3.connection.HTTPConnection object at 0x7f1d9c17c128>: Failed to establish a new connection: [Errno 111] Connection refused

During handling of the above exception, another exception occurred:

Traceback (most recent call last):
  File "/home/cppxaxa/.local/lib/python3.6/site-packages/requests/adapters.py", line 449, in send
    timeout=timeout
  File "/home/cppxaxa/.local/lib/python3.6/site-packages/urllib3/connectionpool.py", line 720, in urlopen
    method, url, error=e, _pool=self, _stacktrace=sys.exc_info()[2]
  File "/home/cppxaxa/.local/lib/python3.6/site-packages/urllib3/util/retry.py", line 436, in increment
    raise MaxRetryError(_pool, url, error or ResponseError(cause))
urllib3.exceptions.MaxRetryError: HTTPConnectionPool(host='127.0.0.1', port=8529): Max retries exceeded with url: /_api/user/root/database (Caused by NewConnectionError('<urllib3.connection.HTTPConnection object at 0x7f1d9c17c128>: Failed to establish a new connection: [Errno 111] Connection refused',))

During handling of the above exception, another exception occurred:

Traceback (most recent call last):
  File "/home/cppxaxa/.local/lib/python3.6/site-packages/flask/app.py", line 2446, in wsgi_app
    response = self.full_dispatch_request()
  File "/home/cppxaxa/.local/lib/python3.6/site-packages/flask/app.py", line 1951, in full_dispatch_request
    rv = self.handle_user_exception(e)
  File "/home/cppxaxa/.local/lib/python3.6/site-packages/flask/app.py", line 1820, in handle_user_exception
    reraise(exc_type, exc_value, tb)
  File "/home/cppxaxa/.local/lib/python3.6/site-packages/flask/_compat.py", line 39, in reraise
    raise value
  File "/home/cppxaxa/.local/lib/python3.6/site-packages/flask/app.py", line 1949, in full_dispatch_request
    rv = self.dispatch_request()
  File "/home/cppxaxa/.local/lib/python3.6/site-packages/flask/app.py", line 1935, in dispatch_request
    return self.view_functions[rule.endpoint](**req.view_args)
  File "/home/cppxaxa/Downloads/ICAN/ScriptServer/ImageDescriptors/QAService.py", line 52, in qaProcessor
    conn = Connection(username='root', password='')
  File "/home/cppxaxa/.local/lib/python3.6/site-packages/pyArango/connection.py", line 123, in __init__
    self.reload()
  File "/home/cppxaxa/.local/lib/python3.6/site-packages/pyArango/connection.py", line 140, in reload
    r = self.session.get(self.databasesURL)
  File "/home/cppxaxa/.local/lib/python3.6/site-packages/pyArango/connection.py", line 43, in __call__
    ret = self.fct(*args, **kwargs)
  File "/home/cppxaxa/.local/lib/python3.6/site-packages/requests/sessions.py", line 546, in get
    return self.request('GET', url, **kwargs)
  File "/home/cppxaxa/.local/lib/python3.6/site-packages/requests/sessions.py", line 533, in request
    resp = self.send(prep, **send_kwargs)
  File "/home/cppxaxa/.local/lib/python3.6/site-packages/requests/sessions.py", line 646, in send
    r = adapter.send(request, **kwargs)
  File "/home/cppxaxa/.local/lib/python3.6/site-packages/requests/adapters.py", line 516, in send
    raise ConnectionError(e, request=request)
requests.exceptions.ConnectionError: HTTPConnectionPool(host='127.0.0.1', port=8529): Max retries exceeded with url: /_api/user/root/database (Caused by NewConnectionError('<urllib3.connection.HTTPConnection object at 0x7f1d9c17c128>: Failed to establish a new connection: [Errno 111] Connection refused',))
INFO:werkzeug:127.0.0.1 - - [07/Oct/2019 10:46:48] "[1m[35mGET /qa?cam=5&question=Hello HTTP/1.1[0m" 500 -
===
Unable to establish connection, perhaps arango is not running.
===
ERROR:QAService:Exception on /qa [GET]
Traceback (most recent call last):
  File "/home/cppxaxa/.local/lib/python3.6/site-packages/urllib3/connection.py", line 157, in _new_conn
    (self._dns_host, self.port), self.timeout, **extra_kw
  File "/home/cppxaxa/.local/lib/python3.6/site-packages/urllib3/util/connection.py", line 84, in create_connection
    raise err
  File "/home/cppxaxa/.local/lib/python3.6/site-packages/urllib3/util/connection.py", line 74, in create_connection
    sock.connect(sa)
ConnectionRefusedError: [Errno 111] Connection refused

During handling of the above exception, another exception occurred:

Traceback (most recent call last):
  File "/home/cppxaxa/.local/lib/python3.6/site-packages/urllib3/connectionpool.py", line 672, in urlopen
    chunked=chunked,
  File "/home/cppxaxa/.local/lib/python3.6/site-packages/urllib3/connectionpool.py", line 387, in _make_request
    conn.request(method, url, **httplib_request_kw)
  File "/usr/lib/python3.6/http/client.py", line 1239, in request
    self._send_request(method, url, body, headers, encode_chunked)
  File "/usr/lib/python3.6/http/client.py", line 1285, in _send_request
    self.endheaders(body, encode_chunked=encode_chunked)
  File "/usr/lib/python3.6/http/client.py", line 1234, in endheaders
    self._send_output(message_body, encode_chunked=encode_chunked)
  File "/usr/lib/python3.6/http/client.py", line 1026, in _send_output
    self.send(msg)
  File "/usr/lib/python3.6/http/client.py", line 964, in send
    self.connect()
  File "/home/cppxaxa/.local/lib/python3.6/site-packages/urllib3/connection.py", line 184, in connect
    conn = self._new_conn()
  File "/home/cppxaxa/.local/lib/python3.6/site-packages/urllib3/connection.py", line 169, in _new_conn
    self, "Failed to establish a new connection: %s" % e
urllib3.exceptions.NewConnectionError: <urllib3.connection.HTTPConnection object at 0x7f1d9c0a3400>: Failed to establish a new connection: [Errno 111] Connection refused

During handling of the above exception, another exception occurred:

Traceback (most recent call last):
  File "/home/cppxaxa/.local/lib/python3.6/site-packages/requests/adapters.py", line 449, in send
    timeout=timeout
  File "/home/cppxaxa/.local/lib/python3.6/site-packages/urllib3/connectionpool.py", line 720, in urlopen
    method, url, error=e, _pool=self, _stacktrace=sys.exc_info()[2]
  File "/home/cppxaxa/.local/lib/python3.6/site-packages/urllib3/util/retry.py", line 436, in increment
    raise MaxRetryError(_pool, url, error or ResponseError(cause))
urllib3.exceptions.MaxRetryError: HTTPConnectionPool(host='127.0.0.1', port=8529): Max retries exceeded with url: /_api/user/root/database (Caused by NewConnectionError('<urllib3.connection.HTTPConnection object at 0x7f1d9c0a3400>: Failed to establish a new connection: [Errno 111] Connection refused',))

During handling of the above exception, another exception occurred:

Traceback (most recent call last):
  File "/home/cppxaxa/.local/lib/python3.6/site-packages/flask/app.py", line 2446, in wsgi_app
    response = self.full_dispatch_request()
  File "/home/cppxaxa/.local/lib/python3.6/site-packages/flask/app.py", line 1951, in full_dispatch_request
    rv = self.handle_user_exception(e)
  File "/home/cppxaxa/.local/lib/python3.6/site-packages/flask/app.py", line 1820, in handle_user_exception
    reraise(exc_type, exc_value, tb)
  File "/home/cppxaxa/.local/lib/python3.6/site-packages/flask/_compat.py", line 39, in reraise
    raise value
  File "/home/cppxaxa/.local/lib/python3.6/site-packages/flask/app.py", line 1949, in full_dispatch_request
    rv = self.dispatch_request()
  File "/home/cppxaxa/.local/lib/python3.6/site-packages/flask/app.py", line 1935, in dispatch_request
    return self.view_functions[rule.endpoint](**req.view_args)
  File "/home/cppxaxa/Downloads/ICAN/ScriptServer/ImageDescriptors/QAService.py", line 52, in qaProcessor
    conn = Connection(username='root', password='')
  File "/home/cppxaxa/.local/lib/python3.6/site-packages/pyArango/connection.py", line 123, in __init__
    self.reload()
  File "/home/cppxaxa/.local/lib/python3.6/site-packages/pyArango/connection.py", line 140, in reload
    r = self.session.get(self.databasesURL)
  File "/home/cppxaxa/.local/lib/python3.6/site-packages/pyArango/connection.py", line 43, in __call__
    ret = self.fct(*args, **kwargs)
  File "/home/cppxaxa/.local/lib/python3.6/site-packages/requests/sessions.py", line 546, in get
    return self.request('GET', url, **kwargs)
  File "/home/cppxaxa/.local/lib/python3.6/site-packages/requests/sessions.py", line 533, in request
    resp = self.send(prep, **send_kwargs)
  File "/home/cppxaxa/.local/lib/python3.6/site-packages/requests/sessions.py", line 646, in send
    r = adapter.send(request, **kwargs)
  File "/home/cppxaxa/.local/lib/python3.6/site-packages/requests/adapters.py", line 516, in send
    raise ConnectionError(e, request=request)
requests.exceptions.ConnectionError: HTTPConnectionPool(host='127.0.0.1', port=8529): Max retries exceeded with url: /_api/user/root/database (Caused by NewConnectionError('<urllib3.connection.HTTPConnection object at 0x7f1d9c0a3400>: Failed to establish a new connection: [Errno 111] Connection refused',))
INFO:werkzeug:127.0.0.1 - - [07/Oct/2019 10:46:58] "[1m[35mGET /qa?cam=5&question=Hello HTTP/1.1[0m" 500 -
===
Unable to establish connection, perhaps arango is not running.
===
ERROR:QAService:Exception on /qa [GET]
Traceback (most recent call last):
  File "/home/cppxaxa/.local/lib/python3.6/site-packages/urllib3/connection.py", line 157, in _new_conn
    (self._dns_host, self.port), self.timeout, **extra_kw
  File "/home/cppxaxa/.local/lib/python3.6/site-packages/urllib3/util/connection.py", line 84, in create_connection
    raise err
  File "/home/cppxaxa/.local/lib/python3.6/site-packages/urllib3/util/connection.py", line 74, in create_connection
    sock.connect(sa)
ConnectionRefusedError: [Errno 111] Connection refused

During handling of the above exception, another exception occurred:

Traceback (most recent call last):
  File "/home/cppxaxa/.local/lib/python3.6/site-packages/urllib3/connectionpool.py", line 672, in urlopen
    chunked=chunked,
  File "/home/cppxaxa/.local/lib/python3.6/site-packages/urllib3/connectionpool.py", line 387, in _make_request
    conn.request(method, url, **httplib_request_kw)
  File "/usr/lib/python3.6/http/client.py", line 1239, in request
    self._send_request(method, url, body, headers, encode_chunked)
  File "/usr/lib/python3.6/http/client.py", line 1285, in _send_request
    self.endheaders(body, encode_chunked=encode_chunked)
  File "/usr/lib/python3.6/http/client.py", line 1234, in endheaders
    self._send_output(message_body, encode_chunked=encode_chunked)
  File "/usr/lib/python3.6/http/client.py", line 1026, in _send_output
    self.send(msg)
  File "/usr/lib/python3.6/http/client.py", line 964, in send
    self.connect()
  File "/home/cppxaxa/.local/lib/python3.6/site-packages/urllib3/connection.py", line 184, in connect
    conn = self._new_conn()
  File "/home/cppxaxa/.local/lib/python3.6/site-packages/urllib3/connection.py", line 169, in _new_conn
    self, "Failed to establish a new connection: %s" % e
urllib3.exceptions.NewConnectionError: <urllib3.connection.HTTPConnection object at 0x7f1d9c0ad048>: Failed to establish a new connection: [Errno 111] Connection refused

During handling of the above exception, another exception occurred:

Traceback (most recent call last):
  File "/home/cppxaxa/.local/lib/python3.6/site-packages/requests/adapters.py", line 449, in send
    timeout=timeout
  File "/home/cppxaxa/.local/lib/python3.6/site-packages/urllib3/connectionpool.py", line 720, in urlopen
    method, url, error=e, _pool=self, _stacktrace=sys.exc_info()[2]
  File "/home/cppxaxa/.local/lib/python3.6/site-packages/urllib3/util/retry.py", line 436, in increment
    raise MaxRetryError(_pool, url, error or ResponseError(cause))
urllib3.exceptions.MaxRetryError: HTTPConnectionPool(host='127.0.0.1', port=8529): Max retries exceeded with url: /_api/user/root/database (Caused by NewConnectionError('<urllib3.connection.HTTPConnection object at 0x7f1d9c0ad048>: Failed to establish a new connection: [Errno 111] Connection refused',))

During handling of the above exception, another exception occurred:

Traceback (most recent call last):
  File "/home/cppxaxa/.local/lib/python3.6/site-packages/flask/app.py", line 2446, in wsgi_app
    response = self.full_dispatch_request()
  File "/home/cppxaxa/.local/lib/python3.6/site-packages/flask/app.py", line 1951, in full_dispatch_request
    rv = self.handle_user_exception(e)
  File "/home/cppxaxa/.local/lib/python3.6/site-packages/flask/app.py", line 1820, in handle_user_exception
    reraise(exc_type, exc_value, tb)
  File "/home/cppxaxa/.local/lib/python3.6/site-packages/flask/_compat.py", line 39, in reraise
    raise value
  File "/home/cppxaxa/.local/lib/python3.6/site-packages/flask/app.py", line 1949, in full_dispatch_request
    rv = self.dispatch_request()
  File "/home/cppxaxa/.local/lib/python3.6/site-packages/flask/app.py", line 1935, in dispatch_request
    return self.view_functions[rule.endpoint](**req.view_args)
  File "/home/cppxaxa/Downloads/ICAN/ScriptServer/ImageDescriptors/QAService.py", line 52, in qaProcessor
    conn = Connection(username='root', password='')
  File "/home/cppxaxa/.local/lib/python3.6/site-packages/pyArango/connection.py", line 123, in __init__
    self.reload()
  File "/home/cppxaxa/.local/lib/python3.6/site-packages/pyArango/connection.py", line 140, in reload
    r = self.session.get(self.databasesURL)
  File "/home/cppxaxa/.local/lib/python3.6/site-packages/pyArango/connection.py", line 43, in __call__
    ret = self.fct(*args, **kwargs)
  File "/home/cppxaxa/.local/lib/python3.6/site-packages/requests/sessions.py", line 546, in get
    return self.request('GET', url, **kwargs)
  File "/home/cppxaxa/.local/lib/python3.6/site-packages/requests/sessions.py", line 533, in request
    resp = self.send(prep, **send_kwargs)
  File "/home/cppxaxa/.local/lib/python3.6/site-packages/requests/sessions.py", line 646, in send
    r = adapter.send(request, **kwargs)
  File "/home/cppxaxa/.local/lib/python3.6/site-packages/requests/adapters.py", line 516, in send
    raise ConnectionError(e, request=request)
requests.exceptions.ConnectionError: HTTPConnectionPool(host='127.0.0.1', port=8529): Max retries exceeded with url: /_api/user/root/database (Caused by NewConnectionError('<urllib3.connection.HTTPConnection object at 0x7f1d9c0ad048>: Failed to establish a new connection: [Errno 111] Connection refused',))
INFO:werkzeug:127.0.0.1 - - [07/Oct/2019 10:47:00] "[1m[35mGET /qa?cam=5&question=Hello HTTP/1.1[0m" 500 -

>> STOPPED BY USER
